Workbook

Sheet LEEME
B1: FODA / DAFO / SWOT de viabilidad exportadora – Pymes industriales de Misiones
B2: Cuestionario basado en el Modelo Canvas | Investigación de Mercados Internacionales – Tecnicatura Superior en Comercio Exterior | Versión 2026
B3: Desarrollado y Preparado por el Prof. Hugo César Galván. ™
B4: 1. Para qué sirve
B5: Convierte las respuestas de una entrevista a una pyme industrial en un FODA cuantificado (fortalezas, debilidades, oportunidades y amenazas), en una matriz de cruces FO/FA/DO/DA y en un primer diagnóstico de viabilidad para exportar.
B7: 2. Cómo se usa (6 pasos)
B8: 1) Copie este archivo por cada empresa y complete los datos de la empresa en la hoja VIABILIDAD (celdas amarillas).
B9: 2) Realice la entrevista con la hoja GUIA_ENTREVISTA: cada factor tiene una pregunta abierta y la evidencia a solicitar.
B10: 3) En FormularioFODA marque con una "x" UNA opción de SITUACIÓN y UNA de IMPACTO por fila (solo se completan las celdas amarillas). La columna Control indica OK / pendiente / revisar.
B11: 4) Use la columna Mensaje para dejar el fundamento o el dato que respalda la respuesta.
B12: 5) Revise los resultados en ResumenFODA (gráficos), PART1 FODA (listas de F, D, O, A), PART2 FODA (cruces) y MATRIZ FODA (burbujas).
B13: 6) Lea la conclusión en VIABILIDAD. Las hojas CalculosFoda, CalculoFoda-1, VariablesFoda y Rango son el motor de cálculo: no se editan.
... B21: 4. Ejemplo de carga (una fila del formulario)
B22: Variable | C22: No corresp. | D22: Muy Desfav. | E22: Desfavorable | F22: Favorable | G22: Muy Favorable | H22: Muy insignif | I22: Insignificante | J22: Significante | K22: Muy Signific.
B23: IB3 - Certificaciones y normas de producto | E23: x | J23: x
B24: Lectura del ejemplo: la empresa tiene certificaciones incompletas (Desfavorable), pero son muy importantes para exportar (Significante). Resultado: debilidad de peso alto que aparecerá en PART1 FODA y bajará el puntaje del bloque Propuesta de valor.
B26: 5. Mapa de hojas
B27: FormularioFODA | C27: Cuestionario (entrada de datos). Único lugar donde se carga información.
B28: GUIA_ENTREVISTA | C28: Preguntas abiertas y evidencias para la entrevista (NUEVA).
B29: MATRIZ FODA | C29: Cuenta los cruces F-O, F-A, D-O, D-A por área y grafica el peso de cada cuadrante.
B30: PART2 FODA | C30: Matriz cruzada: cada factor interno frente a las variables externas de las que depende. Es dinámica (antes era manual).
B31: PART1 FODA | C31: Lista de fortalezas/debilidades (internas) y oportunidades/amenazas (externas).
B32: ResumenFODA | C32: Situación ideal, peor y actual por área, con gráficos.
B33: VIABILIDAD | C33: Puntajes por área, índices global interno y externo, conclusión de viabilidad y estrategia dominante (NUEVA).
B34: CalculoFoda-1 | C34: Motor: conteos por categoría, peso relativo y situación ponderada -1/+1.
B35: VariablesFoda | C35: Mapa de dependencias entre factores internos y variables externas.
B36: CalculosFoda | C36: Motor: puntos 0-10 por factor y ponderación por impacto; semáforo.
B37: Rango | C37: Tabla de conversión de % de logro a puntos.
B39: 6. Mapa Canvas -> áreas del cuestionario
B40: Bloque Canvas | C40: Código | D40: Ítems | E40: Pregunta que responde
B41: 1. Segmentos de clientes | C41: IA | D41: 5 | E41: ¿Para quién creamos valor y a qué mercados podría llegar?
B42: 2. Propuesta de valor | C42: IB | D42: 7 | E42: ¿Qué ofrecemos que el mercado externo valore y pueda comprar?
B43: 3. Canales | C43: IC | D43: 5 | E43: ¿Cómo llegamos al cliente del exterior y cómo le entregamos el producto?
B44: 4. Relación con clientes | C44: ID | D44: 5 | E44: ¿Cómo captamos, atendemos y retenemos al cliente externo?
B45: 5. Fuentes de ingresos | C45: IE | D45: 6 | E45: ¿Cuánto y cómo cobramos, y qué margen deja exportar?
B46: 6. Recursos clave | C46: IF | D46: 8 | E46: ¿Con qué recursos productivos, humanos y financieros contamos para exportar?
B47: 7. Actividades clave | C47: IG | D47: 9 | E47: ¿Qué procesos debemos dominar para producir, cumplir y entregar con calidad?
B48: 8. Socios clave | C48: IH | D48: 6 | E48: ¿Quiénes nos ayudan a producir, vender y cumplir en el exterior?
B49: 9. Estructura de costos | C49: II | D49: 6 | E49: ¿Cuánto cuesta producir y exportar, y a partir de qué escala es rentable?
B50: 10. Transversal: gestión y compromiso exportador | C50: IJ | D50: 7 | E50: ¿La dirección está preparada y decidida a sostener un proceso exportador?
...

Sheet FormularioFODA
B1: FORMULARIO DE RELEVAMIENTO – Marque con una "x" UNA opción de SITUACIÓN y UNA de IMPACTO por cada fila (celdas amarillas)
D2: SITUACIÓN | J2: IMPACTO
B3: Variables | D3: No corresp. | E3: Muy Desfav. | F3: Desfavorable | G3: Favorable | H3: Muy Favorable | J3: Muy insignif | K3: Insignificante | L3: Significante | M3: Muy Signific. | O3: Mensaje / observación de la empresa | P3: Control
B4: MODELO DE NEGOCIO (CANVAS) – LADO CLIENTE Y VALOR
B5: Segmentos de Clientes
B6: 1 - Definición de segmentos y países objetivo. Se considera favorable si la empresa tiene definidos, con datos, los tipos de cliente externo (importador, distribuidor, industria, retail) y los 2 o 3 países prioritarios. | C6: =+CalculosFoda!AD3 -> 6.9999 | G6: x | L6: x | P6: =IF(AND(COUNTIF(D6:H6,"x")=1,COUNTIF(J6:M6,"x")=1),"OK",IF(AND(COUNTIF(D6:H6,"x")=0,COUNTIF(J6:M6,"x")=0),"pendiente","revisar")) -> OK
B7: 2 - Conocimiento de las necesidades del cliente externo. Se considera favorable si la empresa conoce qué exige el comprador del exterior (calidad, volumen, plazos, formatos, certificaciones) y no solo lo que pide el mercado interno. | C7: =+CalculosFoda!AD4 -> 6.9999 | G7: x | M7: x | P7: =IF(AND(COUNTIF(D7:H7,"x")=1,COUNTIF(J7:M7,"x")=1),"OK",IF(AND(COUNTIF(D7:H7,"x")=0,COUNTIF(J7:M7,"x")=0),"pendiente","revisar")) -> OK
B8: 3 - Concentración de clientes. Se considera favorable si ningún cliente supera el 40% de las ventas y la cartera está balanceada entre mercado interno y potencial externo. | C8: =+CalculosFoda!AD5 -> 6.9999 | G8: x | L8: x | P8: =IF(AND(COUNTIF(D8:H8,"x")=1,COUNTIF(J8:M8,"x")=1),"OK",IF(AND(COUNTIF(D8:H8,"x")=0,COUNTIF(J8:M8,"x")=0),"pendiente","revisar")) -> OK
B9: 4 - Experiencia previa exportadora. Se considera favorable si la empresa ya exportó (aunque sea de forma esporádica o indirecta, vía un tercero) o cotizó operaciones al exterior. | C9: =+CalculosFoda!AD6 -> 4.9999 | F9: x | L9: x | P9: =IF(AND(COUNTIF(D9:H9,"x")=1,COUNTIF(J9:M9,"x")=1),"OK",IF(AND(COUNTIF(D9:H9,"x")=0,COUNTIF(J9:M9,"x")=0),"pendiente","revisar")) -> OK
B10: 5 - Acceso a información de mercados. Se considera favorable si la empresa consulta fuentes sistemáticas (estadísticas de comercio, cámaras, agencias de promoción, consulados) para elegir destinos y precios. | C10: =+CalculosFoda!AD7 -> 4.9999 | F10: x | M10: x | P10: =IF(AND(COUNTIF(D10:H10,"x")=1,COUNTIF(J10:M10,"x")=1),"OK",IF(AND(COUNTIF(D10:H10,"x")=0,COUNTIF(J10:M10,"x")=0),"pendiente","revisar")) -> OK
B12: Propuesta de Valor
B13: 1 - Diferenciación del producto. Se considera favorable si el producto tiene atributos diferenciales (calidad, diseño, especie o variedad, proceso, origen) que el cliente externo reconoce y valora. | C13: =+CalculosFoda!AD10 -> 4.9999 | F13: x | M13: x | P13: =IF(AND(COUNTIF(D13:H13,"x")=1,COUNTIF(J13:M13,"x")=1),"OK",IF(AND(COUNTIF(D13:H13,"x")=0,COUNTIF(J13:M13,"x")=0),"pendiente","revisar")) -> OK
B14: 2 - Adecuación a requisitos del mercado destino. Se considera favorable si el producto (norma técnica, envase, etiquetado, idioma, unidades) está adaptado como mínimo al 80% de lo que exige el destino elegido. | C14: =+CalculosFoda!AD11 -> 6.9999 | G14: x | L14: x | P14: =IF(AND(COUNTIF(D14:H14,"x")=1,COUNTIF(J14:M14,"x")=1),"OK",IF(AND(COUNTIF(D14:H14,"x")=0,COUNTIF(J14:M14,"x")=0),"pendiente","revisar")) -> OK
B15: 3 - Certificaciones y normas de producto. Se considera favorable si la empresa posee, o tiene en trámite, las certificaciones que exige el destino (p. ej., FSC/PEFC, orgánico, BPM/HACCP, normas técnicas). | C15: =+CalculosFoda!AD12 -> 4.9999 | F15: x | L15: x | P15: =IF(AND(COUNTIF(D15:H15,"x")=1,COUNTIF(J15:M15,"x")=1),"OK",IF(AND(COUNTIF(D15:H15,"x")=0,COUNTIF(J15:M15,"x")=0),"pendiente","revisar")) -> OK
B16: 4 - Competitividad de precio internacional. Se considera favorable si el precio FOB estimado resulta competitivo frente al de los principales oferentes en el mercado destino. | C16: =+CalculosFoda!AD13 -> 9.99985 | H16: x | L16: x | P16: =IF(AND(COUNTIF(D16:H16,"x")=1,COUNTIF(J16:M16,"x")=1),"OK",IF(AND(COUNTIF(D16:H16,"x")=0,COUNTIF(J16:M16,"x")=0),"pendiente","revisar")) -> OK
B17: 5 - Marca, presentación y material comercial. Se considera favorable si la marca está registrada y existen catálogo, ficha técnica y sitio web al menos en inglés o portugués. | C17: =+CalculosFoda!AD14 -> 9.99985 | H17: x | M17: x | P17: =IF(AND(COUNTIF(D17:H17,"x")=1,COUNTIF(J17:M17,"x")=1),"OK",IF(AND(COUNTIF(D17:H17,"x")=0,COUNTIF(J17:M17,"x")=0),"pendiente","revisar")) -> OK
B18: 6 - Origen e identidad regional. Se considera favorable si el origen misionero/NEA (territorio, tradición, sello o indicación geográfica) agrega valor reconocible al producto. | C18: =+CalculosFoda!AD15 -> 4.9999 | F18: x | L18: x | P18: =IF(AND(COUNTIF(D18:H18,"x")=1,COUNTIF(J18:M18,"x")=1),"OK",IF(AND(COUNTIF(D18:H18,"x")=0,COUNTIF(J18:M18,"x")=0),"pendiente","revisar")) -> OK
B19: 7 - Amplitud de línea y desarrollo de nuevos productos. Se considera favorable si existe una línea suficiente para exportar y una política de adaptar o desarrollar productos para nuevos mercados. | C19: =+CalculosFoda!AD16 -> 2.9999 | E19: x | L19: x | P19: =IF(AND(COUNTIF(D19:H19,"x")=1,COUNTIF(J19:M19,"x")=1),"OK",IF(AND(COUNTIF(D19:H19,"x")=0,COUNTIF(J19:M19,"x")=0),"pendiente","revisar")) -> OK
B21: Canales
B22: 1 - Canales de comercialización externos. Se considera favorable si están identificados y evaluados los canales posibles (importador, distribuidor, agente, trading, venta directa, plataformas) y se sabe cuál usar por segmento. | C22: =+CalculosFoda!AD19 -> 6.9999 | G22: x | M22: x | P22: =IF(AND(COUNTIF(D22:H22,"x")=1,COUNTIF(J22:M22,"x")=1),"OK",IF(AND(COUNTIF(D22:H22,"x")=0,COUNTIF(J22:M22,"x")=0),"pendiente","revisar")) -> OK
B23: 2 - Presencia digital y venta online. Se considera favorable si la empresa tiene sitio web activo y perfiles comerciales, y puede responder consultas del exterior en tiempo razonable. | C23: =+CalculosFoda!AD20 -> 2.9999 | E23: x | M23: x | P23: =IF(AND(COUNTIF(D23:H23,"x")=1,COUNTIF(J23:M23,"x")=1),"OK",IF(AND(COUNTIF(D23:H23,"x")=0,COUNTIF(J23:M23,"x")=0),"pendiente","revisar")) -> OK
B24: 3 - Promoción internacional. Se considera favorable si participa o planea participar en ferias, rondas de negocios, misiones comerciales o campañas de promoción. | C24: =+CalculosFoda!AD21 -> 2.9999 | E24: x | L24: x | P24: =IF(AND(COUNTIF(D24:H24,"x")=1,COUNTIF(J24:M24,"x")=1),"OK",IF(AND(COUNTIF(D24:H24,"x")=0,COUNTIF(J24:M24,"x")=0),"pendiente","revisar")) -> OK
B25: 4 - Logística y embalaje de exportación. Se considera favorable si la empresa sabe cotizar bajo Incoterms, dispone de embalaje apto para transporte internacional y conoce opciones de flete y seguro. | C25: =+CalculosFoda!AD22 -> 2.9999 | E25: x | L25: x | P25: =IF(AND(COUNTIF(D25:H25,"x")=1,COUNTIF(J25:M25,"x")=1),"OK",IF(AND(COUNTIF(D25:H25,"x")=0,COUNTIF(J25:M25,"x")=0),"pendiente","revisar")) -> OK
B26: 5 - Gestión documental y aduanera. Se considera favorable si la empresa conoce o tiene acceso a la documentación de exportación (factura, packing list, certificado de origen, permiso de embarque) y a un despachante. | C26: =+CalculosFoda!AD23 -> 2.9999 | E26: x | M26: x | P26: =IF(AND(COUNTIF(D26:H26,"x")=1,COUNTIF(J26:M26,"x")=1),"OK",IF(AND(COUNTIF(D26:H26,"x")=0,COUNTIF(J26:M26,"x")=0),"pendiente","revisar")) -> OK
B28: Relación con Clientes
B29: 1 - Atención y postventa internacional. Se considera favorable si hay un responsable y un procedimiento para atender consultas, pedidos y postventa del exterior con tiempos de respuesta definidos. | C29: =+CalculosFoda!AD26 -> 6.9999 | G29: x | M29: x | P29: =IF(AND(COUNTIF(D29:H29,"x")=1,COUNTIF(J29:M29,"x")=1),"OK",IF(AND(COUNTIF(D29:H29,"x")=0,COUNTIF(J29:M29,"x")=0),"pendiente","revisar")) -> OK
B30: 2 - Comunicación en idioma extranjero. Se considera favorable si el personal comercial puede negociar y redactar en inglés y/o portugués, o cuenta con traductor o intérprete. | C30: =+CalculosFoda!AD27 -> 4.9999 | F30: x | M30: x | P30: =IF(AND(COUNTIF(D30:H30,"x")=1,COUNTIF(J30:M30,"x")=1),"OK",IF(AND(COUNTIF(D30:H30,"x")=0,COUNTIF(J30:M30,"x")=0),"pendiente","revisar")) -> OK
B31: 3 - Contratos y condiciones con compradores. Se considera favorable si se usan contratos o condiciones de venta escritas (precio, Incoterm, forma de pago, resolución de conflictos) y se evalúa la solvencia del comprador. | C31: =+CalculosFoda!AD28 -> 4.9999 | F31: x | L31: x | P31: =IF(AND(COUNTIF(D31:H31,"x")=1,COUNTIF(J31:M31,"x")=1),"OK",IF(AND(COUNTIF(D31:H31,"x")=0,COUNTIF(J31:M31,"x")=0),"pendiente","revisar")) -> OK
B32: 4 - Fidelización y recompra. Se considera favorable si existen mecanismos para sostener la relación (seguimiento, acuerdos de abastecimiento, condiciones especiales) y hay recompra. | C32: =+CalculosFoda!AD29 -> 2.9999 | E32: x | L32: x | P32: =IF(AND(COUNTIF(D32:H32,"x")=1,COUNTIF(J32:M32,"x")=1),"OK",IF(AND(COUNTIF(D32:H32,"x")=0,COUNTIF(J32:M32,"x")=0),"pendiente","revisar")) -> OK
B33: 5 - Gestión de reclamos y devoluciones. Se considera favorable si hay un procedimiento para reclamos, cambios y devoluciones que resuelve los casos sin pérdida relevante del cliente. | C33: =+CalculosFoda!AD30 -> 4.9999 | F33: x | L33: x | P33: =IF(AND(COUNTIF(D33:H33,"x")=1,COUNTIF(J33:M33,"x")=1),"OK",IF(AND(COUNTIF(D33:H33,"x")=0,COUNTIF(J33:M33,"x")=0),"pendiente","revisar")) -> OK
B35: Fuentes de Ingresos
B36: 1 - Evolución de ventas. Se considera favorable si las ventas crecen o se sostienen en términos reales y hay renovación de clientes y nuevos requerimientos. | C36: =+CalculosFoda!AD33 -> 6.9999 | G36: x | M36: x | P36: =IF(AND(COUNTIF(D36:H36,"x")=1,COUNTIF(J36:M36,"x")=1),"OK",IF(AND(COUNTIF(D36:H36,"x")=0,COUNTIF(J36:M36,"x")=0),"pendiente","revisar")) -> OK
B37: 2 - Fijación de precio de exportación. Se considera favorable si existe un método sistematizado para construir el precio (costo, margen, flete, seguro, comisiones, impuestos) según el Incoterm. | C37: =+CalculosFoda!AD34 -> 6.9999 | G37: x | L37: x | P37: =IF(AND(COUNTIF(D37:H37,"x")=1,COUNTIF(J37:M37,"x")=1),"OK",IF(AND(COUNTIF(D37:H37,"x")=0,COUNTIF(J37:M37,"x")=0),"pendiente","revisar")) -> OK
B38: 3 - Margen del producto exportable. Se considera favorable si el margen de contribución soporta descuentos, comisiones, fletes y derechos de exportación sin quedar por debajo del margen del mercado interno. | C38: =+CalculosFoda!AD35 -> 0.99995 | D38: x | L38: x | P38: =IF(AND(COUNTIF(D38:H38,"x")=1,COUNTIF(J38:M38,"x")=1),"OK",IF(AND(COUNTIF(D38:H38,"x")=0,COUNTIF(J38:M38,"x")=0),"pendiente","revisar")) -> OK
B39: 4 - Medios y condiciones de cobro. Se considera favorable si la empresa conoce y puede operar instrumentos de cobro internacional (transferencia anticipada, cobranza documentaria, carta de crédito, seguro de crédito). | C39: =+CalculosFoda!AD36 -> 6.9999 | G39: x | L39: x | P39: =IF(AND(COUNTIF(D39:H39,"x")=1,COUNTIF(J39:M39,"x")=1),"OK",IF(AND(COUNTIF(D39:H39,"x")=0,COUNTIF(J39:M39,"x")=0),"pendiente","revisar")) -> OK
B40: 5 - Diversificación de ingresos. Se considera favorable si los ingresos no dependen de un único producto, cliente o mercado y hay margen para sumar mercados externos. | C40: =+CalculosFoda!AD37 -> 6.9999 | G40: x | L40: x | P40: =IF(AND(COUNTIF(D40:H40,"x")=1,COUNTIF(J40:M40,"x")=1),"OK",IF(AND(COUNTIF(D40:H40,"x")=0,COUNTIF(J40:M40,"x")=0),"pendiente","revisar")) -> OK
B41: 6 - Resistencia a variaciones cambiarias. Se considera favorable si la empresa puede absorber cambios en el tipo de cambio o cubrirse (precios en dólares, costos dolarizados, coberturas). | C41: =+CalculosFoda!AD38 -> 4.9999 | F41: x | J41: x | P41: =IF(AND(COUNTIF(D41:H41,"x")=1,COUNTIF(J41:M41,"x")=1),"OK",IF(AND(COUNTIF(D41:H41,"x")=0,COUNTIF(J41:M41,"x")=0),"pendiente","revisar")) -> OK
B43: MODELO DE NEGOCIO (CANVAS) – LADO OPERACIÓN Y RECURSOS
B44: Recursos Clave
B45: 1 - Capacidad instalada y ociosa. Se considera favorable si existe capacidad ociosa o ampliable de al menos 30% sin comprometer la atención del mercado actual. | C45: =+CalculosFoda!AD41 -> 6.9999 | G45: x | J45: x | P45: =IF(AND(COUNTIF(D45:H45,"x")=1,COUNTIF(J45:M45,"x")=1),"OK",IF(AND(COUNTIF(D45:H45,"x")=0,COUNTIF(J45:M45,"x")=0),"pendiente","revisar")) -> OK
...

Sheet GUIA_ENTREVISTA
B1: GUÍA DE ENTREVISTA – Preguntas abiertas por factor (para el relevamiento a la empresa)
B2: Formule la pregunta guía, pida la evidencia indicada y recién entonces marque situación e impacto en FormularioFODA. Las columnas H e I orientan cómo leer cada factor cuando la empresa entrevistada NO exporta todavía y evalúa iniciar (ver también LEEME §8).
B4: Código | C4: Área / bloque Canvas | D4: Factor | E4: Pregunta guía para la entrevista | F4: Evidencia a solicitar / fuente a consultar | G4: Fila en FormularioFODA | H4: Quién responde | I4: Si la empresa NO exporta: cómo leer la Situación
B5: IA1 | C5: 1. Segmentos de clientes | D5: Definición de segmentos y países objetivo | E5: ¿A qué tipo de clientes y en qué países querría vender? ¿Con qué datos lo decidió? | F5: Lista de países y segmentos priorizados; estudio o fuente consultada. | G5: =+ROW(FormularioFODA!B6) -> 6 | H5: Empresario: datos de cartera y experiencia actuales. Estudiante: investigación de países y segmentos candidatos, a validar con el empresario. | I5: Favorable si, aunque nunca exportó, el equipo ya identificó con datos 2-3 países/segmentos candidatos (puede ser trabajo del estudiante avalado por el empresario). Si no hay ese trabajo previo, es Desfavorable real, no 'No corresponde'.
B6: IA2 | C6: 1. Segmentos de clientes | D6: Conocimiento de las necesidades del cliente externo | E6: ¿Qué le exigiría un comprador de Brasil, Paraguay u otro destino que hoy no le piden en Argentina? | F6: Consultas o cotizaciones recibidas del exterior; fichas de requisitos. | G6: =+ROW(FormularioFODA!B7) -> 7 | H6: Empresario: datos de cartera y experiencia actuales. Estudiante: investigación de países y segmentos candidatos, a validar con el empresario. | I6: Sin exportar, esto casi siempre será Desfavorable o Muy desfavorable: es una brecha real de información, regístrela así en vez de neutralizarla.
B7: IA3 | C7: 1. Segmentos de clientes | D7: Concentración de clientes | E7: ¿Qué porcentaje de las ventas representa su mayor cliente? ¿Y los tres mayores? | F7: Ranking de clientes por facturación del último año. | G7: =+ROW(FormularioFODA!B8) -> 8 | H7: Empresario: datos de cartera y experiencia actuales. Estudiante: investigación de países y segmentos candidatos, a validar con el empresario. | I7: No cambia: se responde con la cartera de clientes doméstica actual, exporte o no la empresa.
B8: IA4 | C8: 1. Segmentos de clientes | D8: Experiencia previa exportadora | E8: ¿Exportó directa o indirectamente, o cotizó alguna vez a un cliente del exterior? ¿Qué aprendió? | F8: Facturas de exportación, permisos de embarque o cotizaciones. | G8: =+ROW(FormularioFODA!B9) -> 9 | H8: Empresario: datos de cartera y experiencia actuales. Estudiante: investigación de países y segmentos candidatos, a validar con el empresario. | I8: Si nunca exportó ni cotizó, marque Muy Desfavorable con naturalidad: es la respuesta correcta, no un fracaso del formulario. Su Impacto suele ser menor en un primer proyecto acompañado por una cámara, consorcio o la propia tecnicatura.
B9: IA5 | C9: 1. Segmentos de clientes | D9: Acceso a información de mercados | E9: ¿De dónde obtiene información sobre precios, demanda y competidores en el exterior? | F9: Fuentes o informes utilizados; suscripciones o contactos institucionales. | G9: =+ROW(FormularioFODA!B10) -> 10 | H9: Empresario: datos de cartera y experiencia actuales. Estudiante: investigación de países y segmentos candidatos, a validar con el empresario. | I9: Evalúe con lo que el empresario y el equipo estudiante ya reunieron a la fecha de la entrevista, aunque sea incipiente.
B10: IB1 | C10: 2. Propuesta de valor | D10: Diferenciación del producto | E10: ¿Por qué un comprador del exterior le compraría a usted y no a otro proveedor? | F10: Fichas técnicas, muestras, testimonios de clientes, premios. | G10: =+ROW(FormularioFODA!B13) -> 13 | H10: Empresario, con apoyo del estudiante para comparar el producto contra los requisitos del destino elegido. | I10: Se responde igual, exporte o no la empresa: use la evidencia doméstica disponible como capacidad transferible.
B11: IB2 | C11: 2. Propuesta de valor | D11: Adecuación a requisitos del mercado destino | E11: ¿Qué cambios necesitaría el producto, el envase o la etiqueta para venderse en el país objetivo? | F11: Comparación de requisitos del destino frente al producto actual. | G11: =+ROW(FormularioFODA!B14) -> 14 | H11: Empresario, con apoyo del estudiante para comparar el producto contra los requisitos del destino elegido. | I11: Se responde igual, exporte o no la empresa: use la evidencia doméstica disponible como capacidad transferible.
B12: IB3 | C12: 2. Propuesta de valor | D12: Certificaciones y normas de producto | E12: ¿Qué certificaciones tiene vigentes y cuáles le piden sus clientes potenciales? | F12: Certificados vigentes con fecha de vencimiento. | G12: =+ROW(FormularioFODA!B15) -> 15 | H12: Empresario, con apoyo del estudiante para comparar el producto contra los requisitos del destino elegido. | I12: Se responde igual, exporte o no la empresa: use la evidencia doméstica disponible como capacidad transferible.
B13: IB4 | C13: 2. Propuesta de valor | D13: Competitividad de precio internacional | E13: ¿Conoce a qué precio vende la competencia en el destino? ¿Cómo se compara el suyo puesto en frontera o puerto? | F13: Comparativo de precios (fuente pública o listas de compradores). | G13: =+ROW(FormularioFODA!B16) -> 16 | H13: Empresario, con apoyo del estudiante para comparar el producto contra los requisitos del destino elegido. | I13: Se responde igual, exporte o no la empresa: use la evidencia doméstica disponible como capacidad transferible.
B14: IB5 | C14: 2. Propuesta de valor | D14: Marca, presentación y material comercial | E14: ¿Tiene la marca registrada (y en el país destino)? ¿Cuenta con catálogo en otro idioma? | F14: Constancia de registro de marca; catálogo y sitio web. | G14: =+ROW(FormularioFODA!B17) -> 17 | H14: Empresario, con apoyo del estudiante para comparar el producto contra los requisitos del destino elegido. | I14: Se responde igual, exporte o no la empresa: use la evidencia doméstica disponible como capacidad transferible.
B15: IB6 | C15: 2. Propuesta de valor | D15: Origen e identidad regional | E15: ¿Su producto comunica su origen? ¿Los compradores lo valoran? | F15: Sellos de origen, historia de marca, material promocional. | G15: =+ROW(FormularioFODA!B18) -> 18 | H15: Empresario, con apoyo del estudiante para comparar el producto contra los requisitos del destino elegido. | I15: Se responde igual, exporte o no la empresa: use la evidencia doméstica disponible como capacidad transferible.
B16: IB7 | C16: 2. Propuesta de valor | D16: Amplitud de línea y desarrollo de nuevos productos | E16: ¿Cuántas líneas o productos podría ofrecer al exterior y qué desarrollos tiene previstos? | F16: Catálogo de productos; proyectos de desarrollo. | G16: =+ROW(FormularioFODA!B19) -> 19 | H16: Empresario, con apoyo del estudiante para comparar el producto contra los requisitos del destino elegido. | I16: Se responde igual, exporte o no la empresa: use la evidencia doméstica disponible como capacidad transferible.
B17: IC1 | C17: 3. Canales | D17: Canales de comercialización externos | E17: ¿A través de quién vendería en el exterior? ¿Qué canales evaluó? | F17: Mapa de canales; contactos iniciales. | G17: =+ROW(FormularioFODA!B22) -> 22 | H17: Empresario: situación comercial/digital actual. Estudiante: propuesta de canales externos, a validar con el empresario. | I17: Es una propuesta, no un hecho: se marca según la investigación del estudiante y la apertura real del empresario a usar ese canal.
B18: IC2 | C18: 3. Canales | D18: Presencia digital y venta online | E18: ¿Recibe consultas por web o redes sociales? ¿En qué idioma y con qué demora responde? | F18: Sitio web, métricas de contacto. | G18: =+ROW(FormularioFODA!B23) -> 23 | H18: Empresario: situación comercial/digital actual. Estudiante: propuesta de canales externos, a validar con el empresario. | I18: Se evalúa la situación digital ACTUAL de la empresa (sitio, redes, tiempos de respuesta): es una capacidad transferible, no requiere haber exportado.
B19: IC3 | C19: 3. Canales | D19: Promoción internacional | E19: ¿Participó en ferias o rondas de negocios? ¿Qué presupuesto de promoción tiene? | F19: Registro de ferias y rondas; presupuesto de promoción. | G19: =+ROW(FormularioFODA!B24) -> 24 | H19: Empresario: situación comercial/digital actual. Estudiante: propuesta de canales externos, a validar con el empresario. | I19: Si nunca participó de una feria o ronda de negocios, Desfavorable/Muy desfavorable es la respuesta honesta.
B20: IC4 | C20: 3. Canales | D20: Logística y embalaje de exportación | E20: ¿Sabe cómo enviaría la mercadería (embalaje, transporte, seguro) y qué Incoterm ofrecería? | F20: Cotizaciones de flete; especificación de embalaje. | G20: =+ROW(FormularioFODA!B25) -> 25 | H20: Empresario: situación comercial/digital actual. Estudiante: propuesta de canales externos, a validar con el empresario. | I20: Se evalúa la capacidad técnica de adaptar embalaje y transporte actuales, aunque nunca se hayan usado para exportar.
B21: IC5 | C21: 3. Canales | D21: Gestión documental y aduanera | E21: ¿Qué documentos necesita para exportar y quién los gestionaría? | F21: Checklist documental; contacto con despachante. | G21: =+ROW(FormularioFODA!B26) -> 26 | H21: Empresario: situación comercial/digital actual. Estudiante: propuesta de canales externos, a validar con el empresario. | I21: Se evalúa el conocimiento o la disposición a averiguarlo (¿sabe a quién consultar?), no la experiencia previa en despachos.
B22: ID1 | C22: 4. Relación con clientes | D22: Atención y postventa internacional | E22: ¿Quién atendería a un cliente del exterior y en qué plazos? | F22: Procedimiento o responsable designado. | G22: =+ROW(FormularioFODA!B29) -> 29 | H22: Empresario (capacidades transferibles del mercado interno: idioma, contratos, atención, reclamos). | I22: Se evalúa la estructura de atención actual y su capacidad de adaptarse a un cliente a distancia y en otro huso horario.
B23: ID2 | C23: 4. Relación con clientes | D23: Comunicación en idioma extranjero | E23: ¿Quién de la empresa puede negociar en portugués o inglés? | F23: Perfil del personal; servicios de traducción contratados. | G23: =+ROW(FormularioFODA!B30) -> 30 | H23: Empresario (capacidades transferibles del mercado interno: idioma, contratos, atención, reclamos). | I23: Capacidad real del personal hoy, exporte o no la empresa.
B24: ID3 | C24: 4. Relación con clientes | D24: Contratos y condiciones con compradores | E24: ¿Usa contratos o condiciones generales de venta? ¿Cómo verifica la solvencia de un comprador? | F24: Modelo de contrato; informes comerciales. | G24: =+ROW(FormularioFODA!B31) -> 31 | H24: Empresario (capacidades transferibles del mercado interno: idioma, contratos, atención, reclamos). | I24: Se evalúa el uso actual de contratos o condiciones de venta con clientes domésticos, como capacidad transferible a un comprador externo.
B25: ID4 | C25: 4. Relación con clientes | D25: Fidelización y recompra | E25: ¿Qué porcentaje de los clientes vuelve a comprar? ¿Cómo los mantiene? | F25: Tasa de recompra; acuerdos vigentes. | G25: =+ROW(FormularioFODA!B32) -> 32 | H25: Empresario (capacidades transferibles del mercado interno: idioma, contratos, atención, reclamos). | I25: Dato doméstico real: aplica igual exporte o no la empresa.
B26: ID5 | C26: 4. Relación con clientes | D26: Gestión de reclamos y devoluciones | E26: ¿Cómo resuelve hoy un reclamo? ¿Podría hacerlo con un cliente a distancia? | F26: Registro de reclamos y tiempos de resolución. | G26: =+ROW(FormularioFODA!B33) -> 33 | H26: Empresario (capacidades transferibles del mercado interno: idioma, contratos, atención, reclamos). | I26: Dato doméstico real: aplica igual exporte o no la empresa.
B27: IE1 | C27: 5. Fuentes de ingresos | D27: Evolución de ventas | E27: ¿Cómo evolucionaron las ventas en los últimos tres años? | F27: Facturación anual de tres años. | G27: =+ROW(FormularioFODA!B36) -> 36 | H27: Empresario: datos reales de ventas y margen. Estudiante: construcción del costeo/precio de exportación hipotético, a validar con el empresario. | I27: Dato doméstico real: aplica igual exporte o no la empresa.
B28: IE2 | C28: 5. Fuentes de ingresos | D28: Fijación de precio de exportación | E28: ¿Cómo calcularía el precio en dólares de una venta al exterior? | F28: Planilla de costeo de exportación. | G28: =+ROW(FormularioFODA!B37) -> 37 | H28: Empresario: datos reales de ventas y margen. Estudiante: construcción del costeo/precio de exportación hipotético, a validar con el empresario. | I28: Se evalúa si existe (o puede construirse con ayuda del estudiante) un método de costeo, no si ya se aplicó a una venta real.
B29: IE3 | C29: 5. Fuentes de ingresos | D29: Margen del producto exportable | E29: ¿Qué margen deja el producto hoy y cuánto podría ceder para exportar? | F29: Margen por producto. | G29: =+ROW(FormularioFODA!B38) -> 38 | H29: Empresario: datos reales de ventas y margen. Estudiante: construcción del costeo/precio de exportación hipotético, a validar con el empresario. | I29: Se estima a partir del margen doméstico actual y de cuánto podría ceder la empresa, sin necesidad de una venta de exportación real.
B30: IE4 | C30: 5. Fuentes de ingresos | D30: Medios y condiciones de cobro | E30: ¿Cómo cobraría una venta al exterior y qué riesgo aceptaría? | F30: Instrumentos habilitados con su banco. | G30: =+ROW(FormularioFODA!B39) -> 39 | H30: Empresario: datos reales de ventas y margen. Estudiante: construcción del costeo/precio de exportación hipotético, a validar con el empresario. | I30: Se evalúa el conocimiento y la disposición del empresario y su banco, no una operación ya realizada.
B31: IE5 | C31: 5. Fuentes de ingresos | D31: Diversificación de ingresos | E31: ¿De cuántos productos, clientes o mercados depende su facturación? | F31: Composición de ventas. | G31: =+ROW(FormularioFODA!B40) -> 40 | H31: Empresario: datos reales de ventas y margen. Estudiante: construcción del costeo/precio de exportación hipotético, a validar con el empresario. | I31: Dato doméstico real: aplica igual exporte o no la empresa.
B32: IE6 | C32: 5. Fuentes de ingresos | D32: Resistencia a variaciones cambiarias | E32: ¿Qué pasa con su rentabilidad si el tipo de cambio se mueve un 10%? | F32: Sensibilidad de márgenes; proporción de costos en dólares. | G32: =+ROW(FormularioFODA!B41) -> 41 | H32: Empresario: datos reales de ventas y margen. Estudiante: construcción del costeo/precio de exportación hipotético, a validar con el empresario. | I32: Dato doméstico real: sensibilidad de costos y márgenes actuales frente al tipo de cambio.
B33: IF1 | C33: 6. Recursos clave | D33: Capacidad instalada y ociosa | E33: ¿Qué porcentaje de su capacidad usa hoy? ¿Podría producir un pedido exportable sin frenar al resto? | F33: Capacidad nominal frente a producción real. | G33: =+ROW(FormularioFODA!B45) -> 45 | H33: Empresario (recursos productivos, financieros y humanos propios). | I33: Se responde igual, exporte o no la empresa: use la evidencia doméstica disponible como capacidad transferible.
B34: IF2 | C34: 6. Recursos clave | D34: Estado y tecnología de la maquinaria | E34: ¿Qué equipos limitan calidad o volumen? ¿Qué inversión requeriría reemplazarlos? | F34: Inventario de equipos y antigüedad. | G34: =+ROW(FormularioFODA!B46) -> 46 | H34: Empresario (recursos productivos, financieros y humanos propios). | I34: Se responde igual, exporte o no la empresa: use la evidencia doméstica disponible como capacidad transferible.
B35: IF3 | C35: 6. Recursos clave | D35: Personal calificado | E35: ¿Cuenta con personal formado y estable en los puestos críticos? | F35: Nómina por calificación; índice de rotación. | G35: =+ROW(FormularioFODA!B47) -> 47 | H35: Empresario (recursos productivos, financieros y humanos propios). | I35: Se responde igual, exporte o no la empresa: use la evidencia doméstica disponible como capacidad transferible.
B36: IF4 | C36: 6. Recursos clave | D36: Formación continua y capacitación en comercio exterior | E36: ¿Capacita a su personal? ¿Alguien tiene formación en comercio exterior? | F36: Plan de capacitación; certificados. | G36: =+ROW(FormularioFODA!B48) -> 48 | H36: Empresario (recursos productivos, financieros y humanos propios). | I36: Se responde igual, exporte o no la empresa: use la evidencia doméstica disponible como capacidad transferible.
B37: IF5 | C37: 6. Recursos clave | D37: Capital de trabajo y capacidad financiera | E37: ¿Podría afrontar 60 a 90 días de plazo de cobro y los costos de embarque? | F37: Flujo de fondos; líneas bancarias. | G37: =+ROW(FormularioFODA!B49) -> 49 | H37: Empresario (recursos productivos, financieros y humanos propios). | I37: Se responde igual, exporte o no la empresa: use la evidencia doméstica disponible como capacidad transferible.
B38: IF6 | C38: 6. Recursos clave | D38: Sistemas de información y gestión | E38: ¿Su sistema permite facturar en moneda extranjera y seguir pedidos? | F38: Sistema utilizado; capturas o reportes. | G38: =+ROW(FormularioFODA!B50) -> 50 | H38: Empresario (recursos productivos, financieros y humanos propios). | I38: Se responde igual, exporte o no la empresa: use la evidencia doméstica disponible como capacidad transferible.
B39: IF7 | C39: 6. Recursos clave | D39: Infraestructura, depósitos y conservación | E39: ¿Cómo conserva y almacena el producto terminado? ¿Tiene espacio para consolidar un embarque? | F39: Fotos, planos y condiciones de depósito. | G39: =+ROW(FormularioFODA!B51) -> 51 | H39: Empresario (recursos productivos, financieros y humanos propios). | I39: Se responde igual, exporte o no la empresa: use la evidencia doméstica disponible como capacidad transferible.
B40: IF8 | C40: 6. Recursos clave | D40: Habilitaciones y registros oficiales | E40: ¿Qué habilitaciones y registros tiene vigentes? ¿Está inscripta como exportadora? | F40: Constancias vigentes. | G40: =+ROW(FormularioFODA!B52) -> 52 | H40: Empresario (recursos productivos, financieros y humanos propios). | I40: Se responde igual, exporte o no la empresa: use la evidencia doméstica disponible como capacidad transferible.
B41: IG1 | C41: 7. Actividades clave | D41: Descripción técnica y estandarización | E41: ¿Existen procedimientos escritos? ¿Obtiene siempre la misma calidad? | F41: Manuales y diagramas de flujo. | G41: =+ROW(FormularioFODA!B55) -> 55 | H41: Empresario, con relevamiento en planta del estudiante cuando sea posible. | I41: Se responde igual, exporte o no la empresa: use la evidencia doméstica disponible como capacidad transferible.
...

Sheet MATRIZ FODA
I1: Izq. arriba: Fortalezas-Oportunidades | Der. arriba: Fortalezas-Amenazas | Izq. abajo: Debilidades-Oportunidades | Der. abajo: Debilidades-Amenazas
B4: AREA INTERNA - VISTO DESDE EL MODELO CANVAS | C4: Fortalezas Oportunidades | D4: Fortalezas Amenazas | E4: Debilidades Oportunidades | F4: Debilidades Amenazas | G4: Variables no Consideradas
B5: =+FormularioFODA!B5 -> Segmentos de Clientes | C5: =SUMPRODUCT(--(LEN('PART2 FODA'!D4:D10)>0)) -> 2 | D5: =SUMPRODUCT(--(LEN('PART2 FODA'!E4:E10)>0)) -> 2 | E5: =SUMPRODUCT(--(LEN('PART2 FODA'!F4:F10)>0)) -> 1 | F5: =SUMPRODUCT(--(LEN('PART2 FODA'!G4:G10)>0)) -> 1 | G5: =SUMPRODUCT(--(LEN('PART2 FODA'!H4:H10)>0)) -> 1
B6: =+FormularioFODA!B12 -> Propuesta de Valor | C6: =SUMPRODUCT(--(LEN('PART2 FODA'!D12:D25)>0)) -> 3 | D6: =SUMPRODUCT(--(LEN('PART2 FODA'!E12:E25)>0)) -> 3 | E6: =SUMPRODUCT(--(LEN('PART2 FODA'!F12:F25)>0)) -> 3 | F6: =SUMPRODUCT(--(LEN('PART2 FODA'!G12:G25)>0)) -> 5 | G6: =SUMPRODUCT(--(LEN('PART2 FODA'!H12:H25)>0)) -> 0
B7: =+FormularioFODA!B21 -> Canales | C7: =SUMPRODUCT(--(LEN('PART2 FODA'!D27:D37)>0)) -> 0 | D7: =SUMPRODUCT(--(LEN('PART2 FODA'!E27:E37)>0)) -> 1 | E7: =SUMPRODUCT(--(LEN('PART2 FODA'!F27:F37)>0)) -> 0 | F7: =SUMPRODUCT(--(LEN('PART2 FODA'!G27:G37)>0)) -> 8 | G7: =SUMPRODUCT(--(LEN('PART2 FODA'!H27:H37)>0)) -> 2
B8: =+FormularioFODA!B28 -> Relación con Clientes | C8: =SUMPRODUCT(--(LEN('PART2 FODA'!D39:D43)>0)) -> 0 | D8: =SUMPRODUCT(--(LEN('PART2 FODA'!E39:E43)>0)) -> 0 | E8: =SUMPRODUCT(--(LEN('PART2 FODA'!F39:F43)>0)) -> 2 | F8: =SUMPRODUCT(--(LEN('PART2 FODA'!G39:G43)>0)) -> 1 | G8: =SUMPRODUCT(--(LEN('PART2 FODA'!H39:H43)>0)) -> 2
B9: =+FormularioFODA!B35 -> Fuentes de Ingresos | C9: =SUMPRODUCT(--(LEN('PART2 FODA'!D45:D53)>0)) -> 2 | D9: =SUMPRODUCT(--(LEN('PART2 FODA'!E45:E53)>0)) -> 4 | E9: =SUMPRODUCT(--(LEN('PART2 FODA'!F45:F53)>0)) -> 0 | F9: =SUMPRODUCT(--(LEN('PART2 FODA'!G45:G53)>0)) -> 1 | G9: =SUMPRODUCT(--(LEN('PART2 FODA'!H45:H53)>0)) -> 2
B10: =+FormularioFODA!B44 -> Recursos Clave | C10: =SUMPRODUCT(--(LEN('PART2 FODA'!D55:D67)>0)) -> 1 | D10: =SUMPRODUCT(--(LEN('PART2 FODA'!E55:E67)>0)) -> 7 | E10: =SUMPRODUCT(--(LEN('PART2 FODA'!F55:F67)>0)) -> 1 | F10: =SUMPRODUCT(--(LEN('PART2 FODA'!G55:G67)>0)) -> 4 | G10: =SUMPRODUCT(--(LEN('PART2 FODA'!H55:H67)>0)) -> 0
B11: =+FormularioFODA!B54 -> Actividades Clave | C11: =SUMPRODUCT(--(LEN('PART2 FODA'!D69:D81)>0)) -> 2 | D11: =SUMPRODUCT(--(LEN('PART2 FODA'!E69:E81)>0)) -> 3 | E11: =SUMPRODUCT(--(LEN('PART2 FODA'!F69:F81)>0)) -> 2 | F11: =SUMPRODUCT(--(LEN('PART2 FODA'!G69:G81)>0)) -> 3 | G11: =SUMPRODUCT(--(LEN('PART2 FODA'!H69:H81)>0)) -> 3
B12: =+FormularioFODA!B65 -> Socios Clave | C12: =SUMPRODUCT(--(LEN('PART2 FODA'!D83:D93)>0)) -> 2 | D12: =SUMPRODUCT(--(LEN('PART2 FODA'!E83:E93)>0)) -> 4 | E12: =SUMPRODUCT(--(LEN('PART2 FODA'!F83:F93)>0)) -> 1 | F12: =SUMPRODUCT(--(LEN('PART2 FODA'!G83:G93)>0)) -> 3 | G12: =SUMPRODUCT(--(LEN('PART2 FODA'!H83:H93)>0)) -> 1
B13: =+FormularioFODA!B73 -> Estructura de Costos | C13: =SUMPRODUCT(--(LEN('PART2 FODA'!D95:D104)>0)) -> 1 | D13: =SUMPRODUCT(--(LEN('PART2 FODA'!E95:E104)>0)) -> 3 | E13: =SUMPRODUCT(--(LEN('PART2 FODA'!F95:F104)>0)) -> 2 | F13: =SUMPRODUCT(--(LEN('PART2 FODA'!G95:G104)>0)) -> 1 | G13: =SUMPRODUCT(--(LEN('PART2 FODA'!H95:H104)>0)) -> 3
B14: =+FormularioFODA!B82 -> Gestión y Compromiso Exportador | C14: =SUMPRODUCT(--(LEN('PART2 FODA'!D106:D114)>0)) -> 1 | D14: =SUMPRODUCT(--(LEN('PART2 FODA'!E106:E114)>0)) -> 1 | E14: =SUMPRODUCT(--(LEN('PART2 FODA'!F106:F114)>0)) -> 0 | F14: =SUMPRODUCT(--(LEN('PART2 FODA'!G106:G114)>0)) -> 3 | G14: =SUMPRODUCT(--(LEN('PART2 FODA'!H106:H114)>0)) -> 4
B15: Total de cruces | C15: =SUM(C5:C14) -> 14 | D15: =SUM(D5:D14) -> 28 | E15: =SUM(E5:E14) -> 12 | F15: =SUM(F5:F14) -> 30 | G15: =SUM(G5:G14) -> 18
B16: % sobre cruces evaluados | C16: =IF(SUM($C$15:$F$15)=0,0,C15/SUM($C$15:$F$15)) -> 0.16666667 | D16: =IF(SUM($C$15:$F$15)=0,0,D15/SUM($C$15:$F$15)) -> 0.33333333 | E16: =IF(SUM($C$15:$F$15)=0,0,E15/SUM($C$15:$F$15)) -> 0.14285714 | F16: =IF(SUM($C$15:$F$15)=0,0,F15/SUM($C$15:$F$15)) -> 0.35714286
D18: Oportunidades | E18: Amenazas
C19: Fortalezas | D19: =+C15 -> 14 | E19: =+D15 -> 28
C20: Debilidades | D20: =+E15 -> 12 | E20: =+F15 -> 30
B22: Datos auxiliares del gráfico de burbujas (no borrar)
B23: Cuadrante | C23: X | D23: Y | E23: Tamaño (%)
B24: FO - Ofensiva | C24: 4 | D24: 6 | E24: =+C16 -> 0.16666667
B25: FA - Defensiva | C25: 8 | D25: 6 | E25: =+D16 -> 0.33333333
B26: DO - Reorientación | C26: 4 | D26: 2 | E26: =+E16 -> 0.14285714
B27: DA - Supervivencia | C27: 8 | D27: 2 | E27: =+F16 -> 0.35714286

Sheet PART2 FODA
B2: AMBITO INTERNO | C2: Factores Internos | D2: Fortalezas-Oportunidades | E2: Fortalezas-Amenazas | F2: Debilidades-Oportunidades | G2: Debilidades-Amenazas | H2: Variables no consideradas
B3: Se cruza cada factor interno con las variables externas de las que depende (hoja VariablesFoda); el cuadrante surge de la situación cargada.
B4: =+FormularioFODA!B5 -> Segmentos de Clientes | C4: =+CalculosFoda!AF3 -> Definición de segmentos y países objetivo | D4: =IF(AND(OR('CalculoFoda-1'!H3=1,'CalculoFoda-1'!I3=1),OR('CalculoFoda-1'!H129=1,'CalculoFoda-1'!I129=1)),CalculosFoda!AF129,"") | E4: =IF(AND(OR('CalculoFoda-1'!H3=1,'CalculoFoda-1'!I3=1),OR('CalculoFoda-1'!F129=1,'CalculoFoda-1'!G129=1)),CalculosFoda!AF129,"") -> Tamaño y crecimiento del mercado destino | F4: =IF(AND(OR('CalculoFoda-1'!F3=1,'CalculoFoda-1'!G3=1),OR('CalculoFoda-1'!H129=1,'CalculoFoda-1'!I129=1)),CalculosFoda!AF129,"") | G4: =IF(AND(OR('CalculoFoda-1'!F3=1,'CalculoFoda-1'!G3=1),OR('CalculoFoda-1'!F129=1,'CalculoFoda-1'!G129=1)),CalculosFoda!AF129,"") | H4: =IF(OR(NOT(OR('CalculoFoda-1'!F3=1,'CalculoFoda-1'!G3=1,'CalculoFoda-1'!H3=1,'CalculoFoda-1'!I3=1)),NOT(OR('CalculoFoda-1'!F129=1,'CalculoFoda-1'!G129=1,'CalculoFoda-1'!H129=1,'CalculoFoda-1'!I129=1))),"sin dato: "&CalculosFoda!AF129,"")
D5: =IF(AND(OR('CalculoFoda-1'!H3=1,'CalculoFoda-1'!I3=1),OR('CalculoFoda-1'!H132=1,'CalculoFoda-1'!I132=1)),CalculosFoda!AF132,"") -> Cambios del mercado e inteligencia comercial | E5: =IF(AND(OR('CalculoFoda-1'!H3=1,'CalculoFoda-1'!I3=1),OR('CalculoFoda-1'!F132=1,'CalculoFoda-1'!G132=1)),CalculosFoda!AF132,"") | F5: =IF(AND(OR('CalculoFoda-1'!F3=1,'CalculoFoda-1'!G3=1),OR('CalculoFoda-1'!H132=1,'CalculoFoda-1'!I132=1)),CalculosFoda!AF132,"") | G5: =IF(AND(OR('CalculoFoda-1'!F3=1,'CalculoFoda-1'!G3=1),OR('CalculoFoda-1'!F132=1,'CalculoFoda-1'!G132=1)),CalculosFoda!AF132,"") | H5: =IF(OR(NOT(OR('CalculoFoda-1'!F3=1,'CalculoFoda-1'!G3=1,'CalculoFoda-1'!H3=1,'CalculoFoda-1'!I3=1)),NOT(OR('CalculoFoda-1'!F132=1,'CalculoFoda-1'!G132=1,'CalculoFoda-1'!H132=1,'CalculoFoda-1'!I132=1))),"sin dato: "&CalculosFoda!AF132,"")
C6: =+CalculosFoda!AF4 -> Conocimiento de las necesidades del cliente externo | D6: =IF(AND(OR('CalculoFoda-1'!H4=1,'CalculoFoda-1'!I4=1),OR('CalculoFoda-1'!H105=1,'CalculoFoda-1'!I105=1)),CalculosFoda!AF105,"") | E6: =IF(AND(OR('CalculoFoda-1'!H4=1,'CalculoFoda-1'!I4=1),OR('CalculoFoda-1'!F105=1,'CalculoFoda-1'!G105=1)),CalculosFoda!AF105,"") -> Afinidad cultural y hábitos de consumo | F6: =IF(AND(OR('CalculoFoda-1'!F4=1,'CalculoFoda-1'!G4=1),OR('CalculoFoda-1'!H105=1,'CalculoFoda-1'!I105=1)),CalculosFoda!AF105,"") | G6: =IF(AND(OR('CalculoFoda-1'!F4=1,'CalculoFoda-1'!G4=1),OR('CalculoFoda-1'!F105=1,'CalculoFoda-1'!G105=1)),CalculosFoda!AF105,"") | H6: =IF(OR(NOT(OR('CalculoFoda-1'!F4=1,'CalculoFoda-1'!G4=1,'CalculoFoda-1'!H4=1,'CalculoFoda-1'!I4=1)),NOT(OR('CalculoFoda-1'!F105=1,'CalculoFoda-1'!G105=1,'CalculoFoda-1'!H105=1,'CalculoFoda-1'!I105=1))),"sin dato: "&CalculosFoda!AF105,"")
C7: =+CalculosFoda!AF5 -> Concentración de clientes | D7: =IF(AND(OR('CalculoFoda-1'!H5=1,'CalculoFoda-1'!I5=1),OR('CalculoFoda-1'!H130=1,'CalculoFoda-1'!I130=1)),CalculosFoda!AF130,"") -> Poder negociador de compradores e importadores | E7: =IF(AND(OR('CalculoFoda-1'!H5=1,'CalculoFoda-1'!I5=1),OR('CalculoFoda-1'!F130=1,'CalculoFoda-1'!G130=1)),CalculosFoda!AF130,"") | F7: =IF(AND(OR('CalculoFoda-1'!F5=1,'CalculoFoda-1'!G5=1),OR('CalculoFoda-1'!H130=1,'CalculoFoda-1'!I130=1)),CalculosFoda!AF130,"") | G7: =IF(AND(OR('CalculoFoda-1'!F5=1,'CalculoFoda-1'!G5=1),OR('CalculoFoda-1'!F130=1,'CalculoFoda-1'!G130=1)),CalculosFoda!AF130,"") | H7: =IF(OR(NOT(OR('CalculoFoda-1'!F5=1,'CalculoFoda-1'!G5=1,'CalculoFoda-1'!H5=1,'CalculoFoda-1'!I5=1)),NOT(OR('CalculoFoda-1'!F130=1,'CalculoFoda-1'!G130=1,'CalculoFoda-1'!H130=1,'CalculoFoda-1'!I130=1))),"sin dato: "&CalculosFoda!AF130,"")
C8: =+CalculosFoda!AF6 -> Experiencia previa exportadora | H8: variable independiente
C9: =+CalculosFoda!AF7 -> Acceso a información de mercados | D9: =IF(AND(OR('CalculoFoda-1'!H7=1,'CalculoFoda-1'!I7=1),OR('CalculoFoda-1'!H132=1,'CalculoFoda-1'!I132=1)),CalculosFoda!AF132,"") | E9: =IF(AND(OR('CalculoFoda-1'!H7=1,'CalculoFoda-1'!I7=1),OR('CalculoFoda-1'!F132=1,'CalculoFoda-1'!G132=1)),CalculosFoda!AF132,"") | F9: =IF(AND(OR('CalculoFoda-1'!F7=1,'CalculoFoda-1'!G7=1),OR('CalculoFoda-1'!H132=1,'CalculoFoda-1'!I132=1)),CalculosFoda!AF132,"") -> Cambios del mercado e inteligencia comercial | G9: =IF(AND(OR('CalculoFoda-1'!F7=1,'CalculoFoda-1'!G7=1),OR('CalculoFoda-1'!F132=1,'CalculoFoda-1'!G132=1)),CalculosFoda!AF132,"") | H9: =IF(OR(NOT(OR('CalculoFoda-1'!F7=1,'CalculoFoda-1'!G7=1,'CalculoFoda-1'!H7=1,'CalculoFoda-1'!I7=1)),NOT(OR('CalculoFoda-1'!F132=1,'CalculoFoda-1'!G132=1,'CalculoFoda-1'!H132=1,'CalculoFoda-1'!I132=1))),"sin dato: "&CalculosFoda!AF132,"")
D10: =IF(AND(OR('CalculoFoda-1'!H7=1,'CalculoFoda-1'!I7=1),OR('CalculoFoda-1'!H113=1,'CalculoFoda-1'!I113=1)),CalculosFoda!AF113,"") | E10: =IF(AND(OR('CalculoFoda-1'!H7=1,'CalculoFoda-1'!I7=1),OR('CalculoFoda-1'!F113=1,'CalculoFoda-1'!G113=1)),CalculosFoda!AF113,"") | F10: =IF(AND(OR('CalculoFoda-1'!F7=1,'CalculoFoda-1'!G7=1),OR('CalculoFoda-1'!H113=1,'CalculoFoda-1'!I113=1)),CalculosFoda!AF113,"") | G10: =IF(AND(OR('CalculoFoda-1'!F7=1,'CalculoFoda-1'!G7=1),OR('CalculoFoda-1'!F113=1,'CalculoFoda-1'!G113=1)),CalculosFoda!AF113,"") -> Conectividad y plataformas de comercio electrónico | H10: =IF(OR(NOT(OR('CalculoFoda-1'!F7=1,'CalculoFoda-1'!G7=1,'CalculoFoda-1'!H7=1,'CalculoFoda-1'!I7=1)),NOT(OR('CalculoFoda-1'!F113=1,'CalculoFoda-1'!G113=1,'CalculoFoda-1'!H113=1,'CalculoFoda-1'!I113=1))),"sin dato: "&CalculosFoda!AF113,"")
B12: =+FormularioFODA!B12 -> Propuesta de Valor | C12: =+CalculosFoda!AF10 -> Diferenciación del producto | D12: =IF(AND(OR('CalculoFoda-1'!H10=1,'CalculoFoda-1'!I10=1),OR('CalculoFoda-1'!H131=1,'CalculoFoda-1'!I131=1)),CalculosFoda!AF131,"") | E12: =IF(AND(OR('CalculoFoda-1'!H10=1,'CalculoFoda-1'!I10=1),OR('CalculoFoda-1'!F131=1,'CalculoFoda-1'!G131=1)),CalculosFoda!AF131,"") | F12: =IF(AND(OR('CalculoFoda-1'!F10=1,'CalculoFoda-1'!G10=1),OR('CalculoFoda-1'!H131=1,'CalculoFoda-1'!I131=1)),CalculosFoda!AF131,"") | G12: =IF(AND(OR('CalculoFoda-1'!F10=1,'CalculoFoda-1'!G10=1),OR('CalculoFoda-1'!F131=1,'CalculoFoda-1'!G131=1)),CalculosFoda!AF131,"") -> Rivalidad y competidores internacionales | H12: =IF(OR(NOT(OR('CalculoFoda-1'!F10=1,'CalculoFoda-1'!G10=1,'CalculoFoda-1'!H10=1,'CalculoFoda-1'!I10=1)),NOT(OR('CalculoFoda-1'!F131=1,'CalculoFoda-1'!G131=1,'CalculoFoda-1'!H131=1,'CalculoFoda-1'!I131=1))),"sin dato: "&CalculosFoda!AF131,"")
D13: =IF(AND(OR('CalculoFoda-1'!H10=1,'CalculoFoda-1'!I10=1),OR('CalculoFoda-1'!H105=1,'CalculoFoda-1'!I105=1)),CalculosFoda!AF105,"") | E13: =IF(AND(OR('CalculoFoda-1'!H10=1,'CalculoFoda-1'!I10=1),OR('CalculoFoda-1'!F105=1,'CalculoFoda-1'!G105=1)),CalculosFoda!AF105,"") | F13: =IF(AND(OR('CalculoFoda-1'!F10=1,'CalculoFoda-1'!G10=1),OR('CalculoFoda-1'!H105=1,'CalculoFoda-1'!I105=1)),CalculosFoda!AF105,"") | G13: =IF(AND(OR('CalculoFoda-1'!F10=1,'CalculoFoda-1'!G10=1),OR('CalculoFoda-1'!F105=1,'CalculoFoda-1'!G105=1)),CalculosFoda!AF105,"") -> Afinidad cultural y hábitos de consumo | H13: =IF(OR(NOT(OR('CalculoFoda-1'!F10=1,'CalculoFoda-1'!G10=1,'CalculoFoda-1'!H10=1,'CalculoFoda-1'!I10=1)),NOT(OR('CalculoFoda-1'!F105=1,'CalculoFoda-1'!G105=1,'CalculoFoda-1'!H105=1,'CalculoFoda-1'!I105=1))),"sin dato: "&CalculosFoda!AF105,"")
C14: =+CalculosFoda!AF11 -> Adecuación a requisitos del mercado destino | D14: =IF(AND(OR('CalculoFoda-1'!H11=1,'CalculoFoda-1'!I11=1),OR('CalculoFoda-1'!H89=1,'CalculoFoda-1'!I89=1)),CalculosFoda!AF89,"") -> Barreras arancelarias y técnicas del destino | E14: =IF(AND(OR('CalculoFoda-1'!H11=1,'CalculoFoda-1'!I11=1),OR('CalculoFoda-1'!F89=1,'CalculoFoda-1'!G89=1)),CalculosFoda!AF89,"") | F14: =IF(AND(OR('CalculoFoda-1'!F11=1,'CalculoFoda-1'!G11=1),OR('CalculoFoda-1'!H89=1,'CalculoFoda-1'!I89=1)),CalculosFoda!AF89,"") | G14: =IF(AND(OR('CalculoFoda-1'!F11=1,'CalculoFoda-1'!G11=1),OR('CalculoFoda-1'!F89=1,'CalculoFoda-1'!G89=1)),CalculosFoda!AF89,"") | H14: =IF(OR(NOT(OR('CalculoFoda-1'!F11=1,'CalculoFoda-1'!G11=1,'CalculoFoda-1'!H11=1,'CalculoFoda-1'!I11=1)),NOT(OR('CalculoFoda-1'!F89=1,'CalculoFoda-1'!G89=1,'CalculoFoda-1'!H89=1,'CalculoFoda-1'!I89=1))),"sin dato: "&CalculosFoda!AF89,"")
D15: =IF(AND(OR('CalculoFoda-1'!H11=1,'CalculoFoda-1'!I11=1),OR('CalculoFoda-1'!H146=1,'CalculoFoda-1'!I146=1)),CalculosFoda!AF146,"") | E15: =IF(AND(OR('CalculoFoda-1'!H11=1,'CalculoFoda-1'!I11=1),OR('CalculoFoda-1'!F146=1,'CalculoFoda-1'!G146=1)),CalculosFoda!AF146,"") -> Requisitos sanitarios y fitosanitarios del destino | F15: =IF(AND(OR('CalculoFoda-1'!F11=1,'CalculoFoda-1'!G11=1),OR('CalculoFoda-1'!H146=1,'CalculoFoda-1'!I146=1)),CalculosFoda!AF146,"") | G15: =IF(AND(OR('CalculoFoda-1'!F11=1,'CalculoFoda-1'!G11=1),OR('CalculoFoda-1'!F146=1,'CalculoFoda-1'!G146=1)),CalculosFoda!AF146,"") | H15: =IF(OR(NOT(OR('CalculoFoda-1'!F11=1,'CalculoFoda-1'!G11=1,'CalculoFoda-1'!H11=1,'CalculoFoda-1'!I11=1)),NOT(OR('CalculoFoda-1'!F146=1,'CalculoFoda-1'!G146=1,'CalculoFoda-1'!H146=1,'CalculoFoda-1'!I146=1))),"sin dato: "&CalculosFoda!AF146,"")
C16: =+CalculosFoda!AF12 -> Certificaciones y normas de producto | D16: =IF(AND(OR('CalculoFoda-1'!H12=1,'CalculoFoda-1'!I12=1),OR('CalculoFoda-1'!H147=1,'CalculoFoda-1'!I147=1)),CalculosFoda!AF147,"") | E16: =IF(AND(OR('CalculoFoda-1'!H12=1,'CalculoFoda-1'!I12=1),OR('CalculoFoda-1'!F147=1,'CalculoFoda-1'!G147=1)),CalculosFoda!AF147,"") | F16: =IF(AND(OR('CalculoFoda-1'!F12=1,'CalculoFoda-1'!G12=1),OR('CalculoFoda-1'!H147=1,'CalculoFoda-1'!I147=1)),CalculosFoda!AF147,"") -> Certificaciones exigidas por los compradores | G16: =IF(AND(OR('CalculoFoda-1'!F12=1,'CalculoFoda-1'!G12=1),OR('CalculoFoda-1'!F147=1,'CalculoFoda-1'!G147=1)),CalculosFoda!AF147,"") | H16: =IF(OR(NOT(OR('CalculoFoda-1'!F12=1,'CalculoFoda-1'!G12=1,'CalculoFoda-1'!H12=1,'CalculoFoda-1'!I12=1)),NOT(OR('CalculoFoda-1'!F147=1,'CalculoFoda-1'!G147=1,'CalculoFoda-1'!H147=1,'CalculoFoda-1'!I147=1))),"sin dato: "&CalculosFoda!AF147,"")
D17: =IF(AND(OR('CalculoFoda-1'!H12=1,'CalculoFoda-1'!I12=1),OR('CalculoFoda-1'!H89=1,'CalculoFoda-1'!I89=1)),CalculosFoda!AF89,"") | E17: =IF(AND(OR('CalculoFoda-1'!H12=1,'CalculoFoda-1'!I12=1),OR('CalculoFoda-1'!F89=1,'CalculoFoda-1'!G89=1)),CalculosFoda!AF89,"") | F17: =IF(AND(OR('CalculoFoda-1'!F12=1,'CalculoFoda-1'!G12=1),OR('CalculoFoda-1'!H89=1,'CalculoFoda-1'!I89=1)),CalculosFoda!AF89,"") -> Barreras arancelarias y técnicas del destino | G17: =IF(AND(OR('CalculoFoda-1'!F12=1,'CalculoFoda-1'!G12=1),OR('CalculoFoda-1'!F89=1,'CalculoFoda-1'!G89=1)),CalculosFoda!AF89,"") | H17: =IF(OR(NOT(OR('CalculoFoda-1'!F12=1,'CalculoFoda-1'!G12=1,'CalculoFoda-1'!H12=1,'CalculoFoda-1'!I12=1)),NOT(OR('CalculoFoda-1'!F89=1,'CalculoFoda-1'!G89=1,'CalculoFoda-1'!H89=1,'CalculoFoda-1'!I89=1))),"sin dato: "&CalculosFoda!AF89,"")
C18: =+CalculosFoda!AF13 -> Competitividad de precio internacional | D18: =IF(AND(OR('CalculoFoda-1'!H13=1,'CalculoFoda-1'!I13=1),OR('CalculoFoda-1'!H97=1,'CalculoFoda-1'!I97=1)),CalculosFoda!AF97,"") | E18: =IF(AND(OR('CalculoFoda-1'!H13=1,'CalculoFoda-1'!I13=1),OR('CalculoFoda-1'!F97=1,'CalculoFoda-1'!G97=1)),CalculosFoda!AF97,"") -> Tipo de cambio y competitividad | F18: =IF(AND(OR('CalculoFoda-1'!F13=1,'CalculoFoda-1'!G13=1),OR('CalculoFoda-1'!H97=1,'CalculoFoda-1'!I97=1)),CalculosFoda!AF97,"") | G18: =IF(AND(OR('CalculoFoda-1'!F13=1,'CalculoFoda-1'!G13=1),OR('CalculoFoda-1'!F97=1,'CalculoFoda-1'!G97=1)),CalculosFoda!AF97,"") | H18: =IF(OR(NOT(OR('CalculoFoda-1'!F13=1,'CalculoFoda-1'!G13=1,'CalculoFoda-1'!H13=1,'CalculoFoda-1'!I13=1)),NOT(OR('CalculoFoda-1'!F97=1,'CalculoFoda-1'!G97=1,'CalculoFoda-1'!H97=1,'CalculoFoda-1'!I97=1))),"sin dato: "&CalculosFoda!AF97,"")
D19: =IF(AND(OR('CalculoFoda-1'!H13=1,'CalculoFoda-1'!I13=1),OR('CalculoFoda-1'!H102=1,'CalculoFoda-1'!I102=1)),CalculosFoda!AF102,"") -> Precios internacionales del producto | E19: =IF(AND(OR('CalculoFoda-1'!H13=1,'CalculoFoda-1'!I13=1),OR('CalculoFoda-1'!F102=1,'CalculoFoda-1'!G102=1)),CalculosFoda!AF102,"") | F19: =IF(AND(OR('CalculoFoda-1'!F13=1,'CalculoFoda-1'!G13=1),OR('CalculoFoda-1'!H102=1,'CalculoFoda-1'!I102=1)),CalculosFoda!AF102,"") | G19: =IF(AND(OR('CalculoFoda-1'!F13=1,'CalculoFoda-1'!G13=1),OR('CalculoFoda-1'!F102=1,'CalculoFoda-1'!G102=1)),CalculosFoda!AF102,"") | H19: =IF(OR(NOT(OR('CalculoFoda-1'!F13=1,'CalculoFoda-1'!G13=1,'CalculoFoda-1'!H13=1,'CalculoFoda-1'!I13=1)),NOT(OR('CalculoFoda-1'!F102=1,'CalculoFoda-1'!G102=1,'CalculoFoda-1'!H102=1,'CalculoFoda-1'!I102=1))),"sin dato: "&CalculosFoda!AF102,"")
D20: =IF(AND(OR('CalculoFoda-1'!H13=1,'CalculoFoda-1'!I13=1),OR('CalculoFoda-1'!H131=1,'CalculoFoda-1'!I131=1)),CalculosFoda!AF131,"") | E20: =IF(AND(OR('CalculoFoda-1'!H13=1,'CalculoFoda-1'!I13=1),OR('CalculoFoda-1'!F131=1,'CalculoFoda-1'!G131=1)),CalculosFoda!AF131,"") -> Rivalidad y competidores internacionales | F20: =IF(AND(OR('CalculoFoda-1'!F13=1,'CalculoFoda-1'!G13=1),OR('CalculoFoda-1'!H131=1,'CalculoFoda-1'!I131=1)),CalculosFoda!AF131,"") | G20: =IF(AND(OR('CalculoFoda-1'!F13=1,'CalculoFoda-1'!G13=1),OR('CalculoFoda-1'!F131=1,'CalculoFoda-1'!G131=1)),CalculosFoda!AF131,"") | H20: =IF(OR(NOT(OR('CalculoFoda-1'!F13=1,'CalculoFoda-1'!G13=1,'CalculoFoda-1'!H13=1,'CalculoFoda-1'!I13=1)),NOT(OR('CalculoFoda-1'!F131=1,'CalculoFoda-1'!G131=1,'CalculoFoda-1'!H131=1,'CalculoFoda-1'!I131=1))),"sin dato: "&CalculosFoda!AF131,"")
C21: =+CalculosFoda!AF14 -> Marca, presentación y material comercial | D21: =IF(AND(OR('CalculoFoda-1'!H14=1,'CalculoFoda-1'!I14=1),OR('CalculoFoda-1'!H92=1,'CalculoFoda-1'!I92=1)),CalculosFoda!AF92,"") -> Propiedad intelectual y seguridad jurídica | E21: =IF(AND(OR('CalculoFoda-1'!H14=1,'CalculoFoda-1'!I14=1),OR('CalculoFoda-1'!F92=1,'CalculoFoda-1'!G92=1)),CalculosFoda!AF92,"") | F21: =IF(AND(OR('CalculoFoda-1'!F14=1,'CalculoFoda-1'!G14=1),OR('CalculoFoda-1'!H92=1,'CalculoFoda-1'!I92=1)),CalculosFoda!AF92,"") | G21: =IF(AND(OR('CalculoFoda-1'!F14=1,'CalculoFoda-1'!G14=1),OR('CalculoFoda-1'!F92=1,'CalculoFoda-1'!G92=1)),CalculosFoda!AF92,"") | H21: =IF(OR(NOT(OR('CalculoFoda-1'!F14=1,'CalculoFoda-1'!G14=1,'CalculoFoda-1'!H14=1,'CalculoFoda-1'!I14=1)),NOT(OR('CalculoFoda-1'!F92=1,'CalculoFoda-1'!G92=1,'CalculoFoda-1'!H92=1,'CalculoFoda-1'!I92=1))),"sin dato: "&CalculosFoda!AF92,"")
C22: =+CalculosFoda!AF15 -> Origen e identidad regional | D22: =IF(AND(OR('CalculoFoda-1'!H15=1,'CalculoFoda-1'!I15=1),OR('CalculoFoda-1'!H107=1,'CalculoFoda-1'!I107=1)),CalculosFoda!AF107,"") | E22: =IF(AND(OR('CalculoFoda-1'!H15=1,'CalculoFoda-1'!I15=1),OR('CalculoFoda-1'!F107=1,'CalculoFoda-1'!G107=1)),CalculosFoda!AF107,"") | F22: =IF(AND(OR('CalculoFoda-1'!F15=1,'CalculoFoda-1'!G15=1),OR('CalculoFoda-1'!H107=1,'CalculoFoda-1'!I107=1)),CalculosFoda!AF107,"") | G22: =IF(AND(OR('CalculoFoda-1'!F15=1,'CalculoFoda-1'!G15=1),OR('CalculoFoda-1'!F107=1,'CalculoFoda-1'!G107=1)),CalculosFoda!AF107,"") -> Valoración del origen y la sustentabilidad | H22: =IF(OR(NOT(OR('CalculoFoda-1'!F15=1,'CalculoFoda-1'!G15=1,'CalculoFoda-1'!H15=1,'CalculoFoda-1'!I15=1)),NOT(OR('CalculoFoda-1'!F107=1,'CalculoFoda-1'!G107=1,'CalculoFoda-1'!H107=1,'CalculoFoda-1'!I107=1))),"sin dato: "&CalculosFoda!AF107,"")
D23: =IF(AND(OR('CalculoFoda-1'!H15=1,'CalculoFoda-1'!I15=1),OR('CalculoFoda-1'!H92=1,'CalculoFoda-1'!I92=1)),CalculosFoda!AF92,"") | E23: =IF(AND(OR('CalculoFoda-1'!H15=1,'CalculoFoda-1'!I15=1),OR('CalculoFoda-1'!F92=1,'CalculoFoda-1'!G92=1)),CalculosFoda!AF92,"") | F23: =IF(AND(OR('CalculoFoda-1'!F15=1,'CalculoFoda-1'!G15=1),OR('CalculoFoda-1'!H92=1,'CalculoFoda-1'!I92=1)),CalculosFoda!AF92,"") -> Propiedad intelectual y seguridad jurídica | G23: =IF(AND(OR('CalculoFoda-1'!F15=1,'CalculoFoda-1'!G15=1),OR('CalculoFoda-1'!F92=1,'CalculoFoda-1'!G92=1)),CalculosFoda!AF92,"") | H23: =IF(OR(NOT(OR('CalculoFoda-1'!F15=1,'CalculoFoda-1'!G15=1,'CalculoFoda-1'!H15=1,'CalculoFoda-1'!I15=1)),NOT(OR('CalculoFoda-1'!F92=1,'CalculoFoda-1'!G92=1,'CalculoFoda-1'!H92=1,'CalculoFoda-1'!I92=1))),"sin dato: "&CalculosFoda!AF92,"")
C24: =+CalculosFoda!AF16 -> Amplitud de línea y desarrollo de nuevos productos | D24: =IF(AND(OR('CalculoFoda-1'!H16=1,'CalculoFoda-1'!I16=1),OR('CalculoFoda-1'!H112=1,'CalculoFoda-1'!I112=1)),CalculosFoda!AF112,"") | E24: =IF(AND(OR('CalculoFoda-1'!H16=1,'CalculoFoda-1'!I16=1),OR('CalculoFoda-1'!F112=1,'CalculoFoda-1'!G112=1)),CalculosFoda!AF112,"") | F24: =IF(AND(OR('CalculoFoda-1'!F16=1,'CalculoFoda-1'!G16=1),OR('CalculoFoda-1'!H112=1,'CalculoFoda-1'!I112=1)),CalculosFoda!AF112,"") | G24: =IF(AND(OR('CalculoFoda-1'!F16=1,'CalculoFoda-1'!G16=1),OR('CalculoFoda-1'!F112=1,'CalculoFoda-1'!G112=1)),CalculosFoda!AF112,"") -> Avances tecnológicos del sector | H24: =IF(OR(NOT(OR('CalculoFoda-1'!F16=1,'CalculoFoda-1'!G16=1,'CalculoFoda-1'!H16=1,'CalculoFoda-1'!I16=1)),NOT(OR('CalculoFoda-1'!F112=1,'CalculoFoda-1'!G112=1,'CalculoFoda-1'!H112=1,'CalculoFoda-1'!I112=1))),"sin dato: "&CalculosFoda!AF112,"")
D25: =IF(AND(OR('CalculoFoda-1'!H16=1,'CalculoFoda-1'!I16=1),OR('CalculoFoda-1'!H129=1,'CalculoFoda-1'!I129=1)),CalculosFoda!AF129,"") | E25: =IF(AND(OR('CalculoFoda-1'!H16=1,'CalculoFoda-1'!I16=1),OR('CalculoFoda-1'!F129=1,'CalculoFoda-1'!G129=1)),CalculosFoda!AF129,"") | F25: =IF(AND(OR('CalculoFoda-1'!F16=1,'CalculoFoda-1'!G16=1),OR('CalculoFoda-1'!H129=1,'CalculoFoda-1'!I129=1)),CalculosFoda!AF129,"") | G25: =IF(AND(OR('CalculoFoda-1'!F16=1,'CalculoFoda-1'!G16=1),OR('CalculoFoda-1'!F129=1,'CalculoFoda-1'!G129=1)),CalculosFoda!AF129,"") -> Tamaño y crecimiento del mercado destino | H25: =IF(OR(NOT(OR('CalculoFoda-1'!F16=1,'CalculoFoda-1'!G16=1,'CalculoFoda-1'!H16=1,'CalculoFoda-1'!I16=1)),NOT(OR('CalculoFoda-1'!F129=1,'CalculoFoda-1'!G129=1,'CalculoFoda-1'!H129=1,'CalculoFoda-1'!I129=1))),"sin dato: "&CalculosFoda!AF129,"")
B27: =+FormularioFODA!B21 -> Canales | C27: =+CalculosFoda!AF19 -> Canales de comercialización externos | D27: =IF(AND(OR('CalculoFoda-1'!H19=1,'CalculoFoda-1'!I19=1),OR('CalculoFoda-1'!H127=1,'CalculoFoda-1'!I127=1)),CalculosFoda!AF127,"") | E27: =IF(AND(OR('CalculoFoda-1'!H19=1,'CalculoFoda-1'!I19=1),OR('CalculoFoda-1'!F127=1,'CalculoFoda-1'!G127=1)),CalculosFoda!AF127,"") | F27: =IF(AND(OR('CalculoFoda-1'!F19=1,'CalculoFoda-1'!G19=1),OR('CalculoFoda-1'!H127=1,'CalculoFoda-1'!I127=1)),CalculosFoda!AF127,"") | G27: =IF(AND(OR('CalculoFoda-1'!F19=1,'CalculoFoda-1'!G19=1),OR('CalculoFoda-1'!F127=1,'CalculoFoda-1'!G127=1)),CalculosFoda!AF127,"") | H27: =IF(OR(NOT(OR('CalculoFoda-1'!F19=1,'CalculoFoda-1'!G19=1,'CalculoFoda-1'!H19=1,'CalculoFoda-1'!I19=1)),NOT(OR('CalculoFoda-1'!F127=1,'CalculoFoda-1'!G127=1,'CalculoFoda-1'!H127=1,'CalculoFoda-1'!I127=1))),"sin dato: "&CalculosFoda!AF127,"") -> sin dato: Barreras de entrada al mercado destino
D28: =IF(AND(OR('CalculoFoda-1'!H19=1,'CalculoFoda-1'!I19=1),OR('CalculoFoda-1'!H113=1,'CalculoFoda-1'!I113=1)),CalculosFoda!AF113,"") | E28: =IF(AND(OR('CalculoFoda-1'!H19=1,'CalculoFoda-1'!I19=1),OR('CalculoFoda-1'!F113=1,'CalculoFoda-1'!G113=1)),CalculosFoda!AF113,"") -> Conectividad y plataformas de comercio electrónico | F28: =IF(AND(OR('CalculoFoda-1'!F19=1,'CalculoFoda-1'!G19=1),OR('CalculoFoda-1'!H113=1,'CalculoFoda-1'!I113=1)),CalculosFoda!AF113,"") | G28: =IF(AND(OR('CalculoFoda-1'!F19=1,'CalculoFoda-1'!G19=1),OR('CalculoFoda-1'!F113=1,'CalculoFoda-1'!G113=1)),CalculosFoda!AF113,"") | H28: =IF(OR(NOT(OR('CalculoFoda-1'!F19=1,'CalculoFoda-1'!G19=1,'CalculoFoda-1'!H19=1,'CalculoFoda-1'!I19=1)),NOT(OR('CalculoFoda-1'!F113=1,'CalculoFoda-1'!G113=1,'CalculoFoda-1'!H113=1,'CalculoFoda-1'!I113=1))),"sin dato: "&CalculosFoda!AF113,"")
